<?xml version="1.0" ?>
<robot name="base_link_linear" xmlns:xacro="http://www.ros.org/wiki/xacro">

<xacro:include filename="$(find base_link_linear_description)/urdf/materials.xacro" />
<xacro:include filename="$(find base_link_linear_description)/urdf/linear.trans" />
<xacro:include filename="$(find base_link_linear_description)/urdf/linear.gazebo" />
<xacro:include filename="$(find base_link_linear_controller)/ros2_control/base_link_linear.ros2_control.xacro" />
<link name="base_link">
  <inertial>
    <origin xyz="0.00036492580961800734 -0.006364797616936964 0.004905590919618636" rpy="0 0 0"/>
    <mass value="0.03336098454176251"/>
    <inertia ixx="5e-06" iyy="7e-06" izz="1.2e-05" ixy="0.0" iyz="-0.0" ixz="-0.0"/>
  </inertial>
  <visual>
    <origin xyz="0 0 0" rpy="0 0 0"/>
    <geometry>
      <mesh filename="file://$(find base_link_linear_description)/meshes/base_link.stl" scale="0.001 0.001 0.001"/>
    </geometry>
    <material name="silver"/>
  </visual>
  <collision>
    <origin xyz="0 0 0" rpy="0 0 0"/>
    <geometry>
      <mesh filename="file://$(find base_link_linear_description)/meshes/base_link_.stl" scale="0.001 0.001 0.001"/>
    </geometry>
  </collision>
</link>

<link name="grip_mount_1">
  <inertial>
    <origin xyz="-0.00034136005542522146 0.015547767390796129 0.01883273293370806" rpy="0 0 0"/>
    <mass value="0.026038448039166225"/>
    <inertia ixx="5e-06" iyy="4e-06" izz="5e-06" ixy="0.0" iyz="-1e-06" ixz="0.0"/>
  </inertial>
  <visual>
    <origin xyz="-0.000365 0.006365 -0.008562" rpy="0 0 0"/>
    <geometry>
      <mesh filename="file://$(find base_link_linear_description)/meshes/grip_mount_1.stl" scale="0.001 0.001 0.001"/>
    </geometry>
    <material name="black"/>
  </visual>
  <collision>
    <origin xyz="-0.000365 0.006365 -0.008562" rpy="0 0 0"/>
    <geometry>
      <mesh filename="file://$(find base_link_linear_description)/meshes/grip_mount_1.stl" scale="0.001 0.001 0.001"/>
    </geometry>
  </collision>
</link>

<link name="left_mount_1">
  <inertial>
    <origin xyz="-0.012312197013134553 0.010499353929422754 0.01616872816060999" rpy="0 0 0"/>
    <mass value="0.005850260501194334"/>
    <inertia ixx="1e-06" iyy="1e-06" izz="1e-06" ixy="-0.0" iyz="0.0" ixz="0.0"/>
  </inertial>
  <visual>
    <origin xyz="0.022798 0.016079 -0.032689" rpy="0 0 0"/>
    <geometry>
      <mesh filename="file://$(find base_link_linear_description)/meshes/left_mount_1.stl" scale="0.001 0.001 0.001"/>
    </geometry>
    <material name="black"/>
  </visual>
  <collision>
    <origin xyz="0.022798 0.016079 -0.032689" rpy="0 0 0"/>
    <geometry>
      <mesh filename="file://$(find base_link_linear_description)/meshes/left_mount_1.stl" scale="0.001 0.001 0.001"/>
    </geometry>
  </collision>
</link>

<link name="right_mount_1">
  <inertial>
    <origin xyz="0.012015776314503238 0.010500460176130546 0.016402425646791258" rpy="0 0 0"/>
    <mass value="0.005851464483284041"/>
    <inertia ixx="1e-06" iyy="1e-06" izz="1e-06" ixy="0.0" iyz="0.0" ixz="-0.0"/>
  </inertial>
  <visual>
    <origin xyz="-0.022726 0.016079 -0.032981" rpy="0 0 0"/>
    <geometry>
      <mesh filename="file://$(find base_link_linear_description)/meshes/right_mount_1.stl" scale="0.001 0.001 0.001"/>
    </geometry>
    <material name="black"/>
  </visual>
  <collision>
    <origin xyz="-0.022726 0.016079 -0.032981" rpy="0 0 0"/>
    <geometry>
      <mesh filename="file://$(find base_link_linear_description)/meshes/right_mount_1.stl" scale="0.001 0.001 0.001"/>
    </geometry>
  </collision>
</link>

<link name="rubber_left_1">
  <inertial>
    <origin xyz="0.004252295929468346 4.91084999865686e-07 0.02544337370871609" rpy="0 0 0"/>
    <mass value="0.008265327612092782"/>
    <inertia ixx="3e-06" iyy="3e-06" izz="1e-06" ixy="-0.0" iyz="-0.0" ixz="-0.0"/>
  </inertial>
  <visual>
    <origin xyz="0.037938 0.005589 -0.06038" rpy="0 0 0"/>
    <geometry>
      <mesh filename="file://$(find base_link_linear_description)/meshes/rubber_left_1.stl" scale="0.001 0.001 0.001"/>
    </geometry>
    <material name="blue"/>
  </visual>
  <collision>
    <origin xyz="0.037938 0.005589 -0.06038" rpy="0 0 0"/>
    <geometry>
      <mesh filename="file://$(find base_link_linear_description)/meshes/rubber_left_1.stl" scale="0.001 0.001 0.001"/>
    </geometry>
  </collision>
</link>

<link name="rubber_right_1">
  <inertial>
    <origin xyz="-0.005023147767699666 4.5740402191025986e-07 0.025301746998458823" rpy="0 0 0"/>
    <mass value="0.008265327612092756"/>
    <inertia ixx="3e-06" iyy="3e-06" izz="1e-06" ixy="-0.0" iyz="0.0" ixz="1e-06"/>
  </inertial>
  <visual>
    <origin xyz="-0.036906 0.005579 -0.061218" rpy="0 0 0"/>
    <geometry>
      <mesh filename="file://$(find base_link_linear_description)/meshes/rubber_right_1.stl" scale="0.001 0.001 0.001"/>
    </geometry>
    <material name="blue"/>
  </visual>
  <collision>
    <origin xyz="-0.036906 0.005579 -0.061218" rpy="0 0 0"/>
    <geometry>
      <mesh filename="file://$(find base_link_linear_description)/meshes/rubber_right_1.stl" scale="0.001 0.001 0.001"/>
    </geometry>
  </collision>
</link>

<link name="t_shirt_1">
  <inertial>
    <origin xyz="0.00012163162070136035 -0.009411539665347687 0.013485226893769523" rpy="0 0 0"/>
    <mass value="0.0026146856075812087"/>
    <inertia ixx="0.0" iyy="1e-06" izz="0.0" ixy="0.0" iyz="0.0" ixz="-0.0"/>
  </inertial>
  <visual>
    <origin xyz="0.000191 0.007667 -0.022124" rpy="0 0 0"/>
    <geometry>
      <mesh filename="file://$(find base_link_linear_description)/meshes/t_shirt_1.stl" scale="0.001 0.001 0.001"/>
    </geometry>
    <material name="black"/>
  </visual>
  <collision>
    <origin xyz="0.000191 0.007667 -0.022124" rpy="0 0 0"/>
    <geometry>
      <mesh filename="file://$(find base_link_linear_description)/meshes/t_shirt_1.stl" scale="0.001 0.001 0.001"/>
    </geometry>
  </collision>
</link>

<joint name="Rigid 20" type="fixed">
  <origin xyz="0.000365 -0.006365 0.008562" rpy="0 0 0"/>
  <parent link="tool_base"/>
  <child link="grip_mount_1"/>
</joint>

<joint name="Slider 22" type="prismatic">
  <origin xyz="-0.022607 -0.008412 0.010565" rpy="0 0 0"/>
  <parent link="t_shirt_1"/>
  <child link="left_mount_1"/>
  <axis xyz="0.817033 -0.0 0.576591"/>
  <limit upper="0.022" lower="-0.003" effort="100" velocity="100"/>
</joint>

<joint name="Slider 23" type="prismatic">
  <origin xyz="0.022917 -0.008412 0.010857" rpy="0 0 0"/>
  <parent link="t_shirt_1"/>
  <child link="right_mount_1"/>
  <axis xyz="0.820609 0.0 -0.57149"/>
  <limit upper="0.003" lower="-0.022" effort="100" velocity="100"/>
</joint>

<joint name="Rigid 24" type="fixed">
  <origin xyz="-0.01514 0.01049 0.027691" rpy="0 0 0"/>
  <parent link="left_mount_1"/>
  <child link="rubber_left_1"/>
</joint>

<joint name="Rigid 25" type="fixed">
  <origin xyz="0.01418 0.0105 0.028237" rpy="0 0 0"/>
  <parent link="right_mount_1"/>
  <child link="rubber_right_1"/>
</joint>

<joint name="Rigid 26" type="fixed">
  <origin xyz="-0.000556 -0.001302 0.013562" rpy="0 0 0"/>
  <parent link="grip_mount_1"/>
  <child link="t_shirt_1"/>
</joint>

<ros2_control name="Robot" type="system">

      <hardware>
        <plugin>base_link_linear_controller/RobotSystem</plugin>
        <param name="position1_joint_name">Slider 22</param>
        <param name="position2_joint_name">Slider 23</param>
        <param name="loop_rate">50</param>
        <param name="device">/dev/ttyACM0</param>
        <param name="baud_rate">115200</param>
        <param name="timeout">1000</param>
      </hardware>
      
      <joint name="Slider 22">
        <command_interface name="position">
          <param name="min">${-2*pi}</param>
          <param name="max">${2*pi}</param>
        </command_interface>
        <!-- <command_interface name="velocity"> 
          <param name="min">-3.15</param>
          <param name="max">3.15</param>
        </command_interface>                     -->
        <state_interface name="position">
          <param name="initial_value">0.0</param>
        </state_interface>
      </joint>

      <joint name="Slider 23">
        <command_interface name="position">
          <param name="min">${-2*pi}</param>
          <param name="max">${2*pi}</param>
        </command_interface>
        <!-- <command_interface name="velocity">
          <param name="min">-3.15</param>
          <param name="max">3.15</param>
        </command_interface>                      -->
        <state_interface name="position">
          <param name="initial_value">0.0</param>
        </state_interface>
      </joint>

    </ros2_control>

</robot>
